[2025-09-25T17:04:01.009+0000] {local_task_job_runner.py:120} INFO - ::group::Pre task execution logs
[2025-09-25T17:04:01.017+0000] {taskinstance.py:2076} INFO - Dependencies all met for dep_context=non-requeueable deps ti=<TaskInstance: hw1.train_model manual__2025-09-25T17:03:42.857299+00:00 [queued]>
[2025-09-25T17:04:01.021+0000] {taskinstance.py:2076} INFO - Dependencies all met for dep_context=requeueable deps ti=<TaskInstance: hw1.train_model manual__2025-09-25T17:03:42.857299+00:00 [queued]>
[2025-09-25T17:04:01.021+0000] {taskinstance.py:2306} INFO - Starting attempt 1 of 2
[2025-09-25T17:04:01.027+0000] {taskinstance.py:2330} INFO - Executing <Task(PythonOperator): train_model> on 2025-09-25 17:03:42.857299+00:00
[2025-09-25T17:04:01.032+0000] {standard_task_runner.py:64} INFO - Started process 44189 to run task
[2025-09-25T17:04:01.034+0000] {standard_task_runner.py:90} INFO - Running: ['***', 'tasks', 'run', 'hw1', 'train_model', 'manual__2025-09-25T17:03:42.857299+00:00', '--job-id', '53', '--raw', '--subdir', 'DAGS_FOLDER/kudryakov_hw1.py', '--cfg-path', '/tmp/tmppyc9j2zb']
[2025-09-25T17:04:01.037+0000] {standard_task_runner.py:91} INFO - Job 53: Subtask train_model
[2025-09-25T17:04:01.064+0000] {task_command.py:426} INFO - Running <TaskInstance: hw1.train_model manual__2025-09-25T17:03:42.857299+00:00 [running]> on host 2b301b74205f
[2025-09-25T17:04:01.116+0000] {taskinstance.py:2648} INFO - Exporting env vars: AIRFLOW_CTX_DAG_OWNER='VLADISLAV KUDRYAKOV' AIRFLOW_CTX_DAG_ID='hw1' AIRFLOW_CTX_TASK_ID='train_model' AIRFLOW_CTX_EXECUTION_DATE='2025-09-25T17:03:42.857299+00:00' AIRFLOW_CTX_TRY_NUMBER='1' AIRFLOW_CTX_DAG_RUN_ID='manual__2025-09-25T17:03:42.857299+00:00'
[2025-09-25T17:04:01.117+0000] {taskinstance.py:430} INFO - ::endgroup::
[2025-09-25T17:04:01.125+0000] {kudryakov_hw1.py:186} INFO - Начали обучение модели
[2025-09-25T17:04:01.126+0000] {taskinstance.py:441} INFO - ::group::Post task execution logs
[2025-09-25T17:04:01.126+0000] {taskinstance.py:2905} ERROR - Task failed with exception
Traceback (most recent call last):
  File "/home/airflow/.local/lib/python3.10/site-packages/airflow/models/taskinstance.py", line 465, in _execute_task
    result = _execute_callable(context=context, **execute_callable_kwargs)
  File "/home/airflow/.local/lib/python3.10/site-packages/airflow/models/taskinstance.py", line 432, in _execute_callable
    return execute_callable(context=context, **execute_callable_kwargs)
  File "/home/airflow/.local/lib/python3.10/site-packages/airflow/models/baseoperator.py", line 401, in wrapper
    return func(self, *args, **kwargs)
  File "/home/airflow/.local/lib/python3.10/site-packages/airflow/operators/python.py", line 235, in execute
    return_value = self.execute_callable()
  File "/home/airflow/.local/lib/python3.10/site-packages/airflow/operators/python.py", line 252, in execute_callable
    return self.python_callable(*self.op_args, **self.op_kwargs)
  File "/opt/airflow/dags/kudryakov_hw1.py", line 188, in train_model
    file = s3_hook.download_file(key=f"2025/processed_data/titanic/titanic_x_train.pkl", bucket_name=S3_BUCKET)
UnboundLocalError: local variable 's3_hook' referenced before assignment
[2025-09-25T17:04:01.132+0000] {taskinstance.py:1206} INFO - Marking task as UP_FOR_RETRY. dag_id=hw1, task_id=train_model, run_id=manual__2025-09-25T17:03:42.857299+00:00, execution_date=20250925T170342, start_date=20250925T170401, end_date=20250925T170401
[2025-09-25T17:04:01.137+0000] {standard_task_runner.py:110} ERROR - Failed to execute job 53 for task train_model (local variable 's3_hook' referenced before assignment; 44189)
[2025-09-25T17:04:01.178+0000] {local_task_job_runner.py:243} INFO - Task exited with return code 1
[2025-09-25T17:04:01.186+0000] {taskinstance.py:3503} INFO - 0 downstream tasks scheduled from follow-on schedule check
[2025-09-25T17:04:01.187+0000] {local_task_job_runner.py:222} INFO - ::endgroup::
