[2025-09-25T20:47:21.753+0000] {local_task_job_runner.py:120} INFO - ::group::Pre task execution logs
[2025-09-25T20:47:21.759+0000] {taskinstance.py:2076} INFO - Dependencies all met for dep_context=non-requeueable deps ti=<TaskInstance: hw1.collect_metrics_pipeline manual__2025-09-25T20:41:58.008627+00:00 [queued]>
[2025-09-25T20:47:21.762+0000] {taskinstance.py:2076} INFO - Dependencies all met for dep_context=requeueable deps ti=<TaskInstance: hw1.collect_metrics_pipeline manual__2025-09-25T20:41:58.008627+00:00 [queued]>
[2025-09-25T20:47:21.762+0000] {taskinstance.py:2306} INFO - Starting attempt 2 of 2
[2025-09-25T20:47:21.766+0000] {taskinstance.py:2330} INFO - Executing <Task(PythonOperator): collect_metrics_pipeline> on 2025-09-25 20:41:58.008627+00:00
[2025-09-25T20:47:21.771+0000] {standard_task_runner.py:64} INFO - Started process 75607 to run task
[2025-09-25T20:47:21.773+0000] {standard_task_runner.py:90} INFO - Running: ['***', 'tasks', 'run', 'hw1', 'collect_metrics_pipeline', 'manual__2025-09-25T20:41:58.008627+00:00', '--job-id', '210', '--raw', '--subdir', 'DAGS_FOLDER/kudryakov_hw1.py', '--cfg-path', '/tmp/tmp54_7dssa']
[2025-09-25T20:47:21.774+0000] {standard_task_runner.py:91} INFO - Job 210: Subtask collect_metrics_pipeline
[2025-09-25T20:47:21.791+0000] {task_command.py:426} INFO - Running <TaskInstance: hw1.collect_metrics_pipeline manual__2025-09-25T20:41:58.008627+00:00 [running]> on host 2b301b74205f
[2025-09-25T20:47:21.821+0000] {taskinstance.py:2648} INFO - Exporting env vars: AIRFLOW_CTX_DAG_OWNER='VLADISLAV KUDRYAKOV' AIRFLOW_CTX_DAG_ID='hw1' AIRFLOW_CTX_TASK_ID='collect_metrics_pipeline' AIRFLOW_CTX_EXECUTION_DATE='2025-09-25T20:41:58.008627+00:00' AIRFLOW_CTX_TRY_NUMBER='2' AIRFLOW_CTX_DAG_RUN_ID='manual__2025-09-25T20:41:58.008627+00:00'
[2025-09-25T20:47:21.822+0000] {taskinstance.py:430} INFO - ::endgroup::
[2025-09-25T20:47:21.826+0000] {kudryakov_hw1.py:240} INFO - Начинаем сбор метрик пайплайна
[2025-09-25T20:47:21.846+0000] {logging_mixin.py:188} INFO - {'pipeline_start': datetime.datetime(2025, 9, 25, 20, 41, 59, 273160), 'pipeline_end': datetime.datetime(2025, 9, 25, 20, 42, 19, 575904), 'total_duration': 20.302744, 'split_and_preprocess_start': datetime.datetime(2025, 9, 25, 20, 42, 2, 581550), 'split_and_preprocess_end': datetime.datetime(2025, 9, 25, 20, 42, 7, 723032), 'train_start': datetime.datetime(2025, 9, 25, 20, 42, 10, 41892), 'train_end': datetime.datetime(2025, 9, 25, 20, 42, 15, 84656), 'train_duration_seconds': 5.04, 'collect_metrics_start': datetime.datetime(2025, 9, 25, 20, 42, 15, 739291), 'collect_metrics_end': datetime.datetime(2025, 9, 25, 20, 42, 19, 575904), 'author': 'VLADISLAV KUDRYAKOV', 'dag_id': 'hw1', 'run_id': 'manual__2025-09-25T20:41:58.008627+00:00'} pipeline_metrics
[2025-09-25T20:47:21.846+0000] {taskinstance.py:441} INFO - ::group::Post task execution logs
[2025-09-25T20:47:21.846+0000] {taskinstance.py:2905} ERROR - Task failed with exception
Traceback (most recent call last):
  File "/home/airflow/.local/lib/python3.10/site-packages/airflow/models/taskinstance.py", line 465, in _execute_task
    result = _execute_callable(context=context, **execute_callable_kwargs)
  File "/home/airflow/.local/lib/python3.10/site-packages/airflow/models/taskinstance.py", line 432, in _execute_callable
    return execute_callable(context=context, **execute_callable_kwargs)
  File "/home/airflow/.local/lib/python3.10/site-packages/airflow/models/baseoperator.py", line 401, in wrapper
    return func(self, *args, **kwargs)
  File "/home/airflow/.local/lib/python3.10/site-packages/airflow/operators/python.py", line 235, in execute
    return_value = self.execute_callable()
  File "/home/airflow/.local/lib/python3.10/site-packages/airflow/operators/python.py", line 252, in execute_callable
    return self.python_callable(*self.op_args, **self.op_kwargs)
  File "/opt/airflow/dags/kudryakov_hw1.py", line 270, in collect_metrics_pipeline
    s3_write_json(s3_hook, pipeline_metrics, S3_BUCKET, S3_KEY_PIPELINE_METRICS)
  File "/opt/airflow/dags/kudryakov_hw1.py", line 54, in s3_write_json
    json_str = json.dumps(data, indent=2, ensure_ascii=False)
  File "/usr/local/lib/python3.10/json/__init__.py", line 238, in dumps
    **kw).encode(obj)
  File "/usr/local/lib/python3.10/json/encoder.py", line 201, in encode
    chunks = list(chunks)
  File "/usr/local/lib/python3.10/json/encoder.py", line 431, in _iterencode
    yield from _iterencode_dict(o, _current_indent_level)
  File "/usr/local/lib/python3.10/json/encoder.py", line 405, in _iterencode_dict
    yield from chunks
  File "/usr/local/lib/python3.10/json/encoder.py", line 438, in _iterencode
    o = _default(o)
  File "/usr/local/lib/python3.10/json/encoder.py", line 179, in default
    raise TypeError(f'Object of type {o.__class__.__name__} '
TypeError: Object of type datetime is not JSON serializable
[2025-09-25T20:47:21.849+0000] {taskinstance.py:1206} INFO - Marking task as FAILED. dag_id=hw1, task_id=collect_metrics_pipeline, run_id=manual__2025-09-25T20:41:58.008627+00:00, execution_date=20250925T204158, start_date=20250925T204721, end_date=20250925T204721
[2025-09-25T20:47:21.853+0000] {standard_task_runner.py:110} ERROR - Failed to execute job 210 for task collect_metrics_pipeline (Object of type datetime is not JSON serializable; 75607)
[2025-09-25T20:47:21.872+0000] {local_task_job_runner.py:243} INFO - Task exited with return code 1
[2025-09-25T20:47:21.878+0000] {taskinstance.py:3503} INFO - 0 downstream tasks scheduled from follow-on schedule check
[2025-09-25T20:47:21.879+0000] {local_task_job_runner.py:222} INFO - ::endgroup::
